Workbook

Sheet Raw Data
A1: Customer ID | B1: Customer Name | C1: Email | D1: City | E1: Frequency | F1: Monetary Value | G1: Last Purchase Date | H1: Recency Days
A2: 1 | B2: Rajesh Kumar | C2: rajesh@email.com | D2: Hyderabad | E2: 4 | F2: 18700 | G2: 2024-08-10 | H2: 6
A3: 2 | B3: Priya Sharma | C3: priya@email.com | D3: Mumbai | E3: 3 | F3: 10200 | G3: 2024-07-15 | H3: 32
A4: 3 | B4: Amit Patel | C4: amit@email.com | D4: Delhi | E4: 3 | F4: 11000 | G4: 2024-08-05 | H4: 11
A5: 4 | B5: Sneha Gupta | C5: sneha@email.com | D5: Bangalore | E5: 2 | F5: 4200 | G5: 2023-12-10 | H5: 562
A6: 5 | B6: Vikram Singh | C6: vikram@email.com | D6: Pune | E6: 3 | F6: 9500 | G6: 2024-06-20 | H6: 57
A7: 6 | B7: Anjali Reddy | C7: anjali@email.com | D7: Hyderabad | E7: 4 | F7: 15600 | G7: 2024-08-18 | H7: 0
A8: 7 | B8: Rahul Chopra | C8: rahul@email.com | D8: Delhi | E8: 2 | F8: 3800 | G8: 2024-02-05 | H8: 193
A9: 8 | B9: Neha Iyer | C9: neha@email.com | D9: Kochi | E9: 3 | F9: 12500 | G9: 2024-07-22 | H9: 25
A10: 9 | B10: Arjun Nair | C10: arjun@email.com | D10: Chennai | E10: 4 | F10: 16800 | G10: 2024-08-12 | H10: 4
A11: 10 | B11: Divya Menon | C11: divya@email.com | D11: Mumbai | E11: 4 | F11: 14200 | G11: 2024-07-18 | H11: 29
A12: 11 | B12: Sanjay Verma | C12: sanjay@email.com | D12: Noida | E12: 3 | F12: 11500 | G12: 2024-06-25 | H12: 52
A13: 12 | B13: Kanika Bhat | C13: kanika@email.com | D13: Bangalore | E13: 1 | F13: 2100 | G13: 2023-11-10 | H13: 614
... A101: 100 | B101: Customer 100 | C101: cust100@email.com | D101: City | E101: 1 | F101: 10100 | G101: 2024-07-20 | H101: 30

Sheet RFM Calculations
A1: Customer ID | B1: Customer Name | C1: Frequency | D1: Monetary Value | E1: Recency Days | F1: R Quartile | G1: F Quartile | H1: M Quartile | I1: RFM Score | J1: Segment
A2: ='Raw Data'!A2 -> 1 | B2: ='Raw Data'!B2 -> Rajesh Kumar | C2: ='Raw Data'!E2 -> 4 | D2: ='Raw Data'!F2 -> 18700 | E2: ='Raw Data'!H2 -> 6 | F2: =IF(E2<=30,4,IF(E2<=90,3,IF(E2<=180,2,1))) -> 4 | G2: =IF(C2=1,1,IF(C2=2,2,IF(C2=3,3,4))) -> 4 | H2: =IF(D2<5000,1,IF(D2<15000,2,IF(D2<30000,3,4))) -> 3 | I2: =CONCATENATE(F2,G2,H2) -> 443 | J2: =IF(VALUE(I2)>=434,"Champions",IF(VALUE(I2)>=334,"Loyal",IF(VALUE(I2)>=234,"Potential",IF(VALUE(I2)>=134,"At Risk",IF(VALUE(I2)>=112,"Churned","Lost"))))) -> Champions
A3: ='Raw Data'!A3 -> 2 | B3: ='Raw Data'!B3 -> Priya Sharma | C3: ='Raw Data'!E3 -> 3 | D3: ='Raw Data'!F3 -> 10200 | E3: ='Raw Data'!H3 -> 32 | F3: =IF(E3<=30,4,IF(E3<=90,3,IF(E3<=180,2,1))) -> 3 | G3: =IF(C3=1,1,IF(C3=2,2,IF(C3=3,3,4))) -> 3 | H3: =IF(D3<5000,1,IF(D3<15000,2,IF(D3<30000,3,4))) -> 2 | I3: =CONCATENATE(F3,G3,H3) -> 332 | J3: =IF(VALUE(I3)>=434,"Champions",IF(VALUE(I3)>=334,"Loyal",IF(VALUE(I3)>=234,"Potential",IF(VALUE(I3)>=134,"At Risk",IF(VALUE(I3)>=112,"Churned","Lost"))))) -> Potential
A4: ='Raw Data'!A4 -> 3 | B4: ='Raw Data'!B4 -> Amit Patel | C4: ='Raw Data'!E4 -> 3 | D4: ='Raw Data'!F4 -> 11000 | E4: ='Raw Data'!H4 -> 11 | F4: =IF(E4<=30,4,IF(E4<=90,3,IF(E4<=180,2,1))) -> 4 | G4: =IF(C4=1,1,IF(C4=2,2,IF(C4=3,3,4))) -> 3 | H4: =IF(D4<5000,1,IF(D4<15000,2,IF(D4<30000,3,4))) -> 2 | I4: =CONCATENATE(F4,G4,H4) -> 432 | J4: =IF(VALUE(I4)>=434,"Champions",IF(VALUE(I4)>=334,"Loyal",IF(VALUE(I4)>=234,"Potential",IF(VALUE(I4)>=134,"At Risk",IF(VALUE(I4)>=112,"Churned","Lost"))))) -> Loyal
A5: ='Raw Data'!A5 -> 4 | B5: ='Raw Data'!B5 -> Sneha Gupta | C5: ='Raw Data'!E5 -> 2 | D5: ='Raw Data'!F5 -> 4200 | E5: ='Raw Data'!H5 -> 562 | F5: =IF(E5<=30,4,IF(E5<=90,3,IF(E5<=180,2,1))) -> 1 | G5: =IF(C5=1,1,IF(C5=2,2,IF(C5=3,3,4))) -> 2 | H5: =IF(D5<5000,1,IF(D5<15000,2,IF(D5<30000,3,4))) -> 1 | I5: =CONCATENATE(F5,G5,H5) -> 121 | J5: =IF(VALUE(I5)>=434,"Champions",IF(VALUE(I5)>=334,"Loyal",IF(VALUE(I5)>=234,"Potential",IF(VALUE(I5)>=134,"At Risk",IF(VALUE(I5)>=112,"Churned","Lost"))))) -> Churned
A6: ='Raw Data'!A6 -> 5 | B6: ='Raw Data'!B6 -> Vikram Singh | C6: ='Raw Data'!E6 -> 3 | D6: ='Raw Data'!F6 -> 9500 | E6: ='Raw Data'!H6 -> 57 | F6: =IF(E6<=30,4,IF(E6<=90,3,IF(E6<=180,2,1))) -> 3 | G6: =IF(C6=1,1,IF(C6=2,2,IF(C6=3,3,4))) -> 3 | H6: =IF(D6<5000,1,IF(D6<15000,2,IF(D6<30000,3,4))) -> 2 | I6: =CONCATENATE(F6,G6,H6) -> 332 | J6: =IF(VALUE(I6)>=434,"Champions",IF(VALUE(I6)>=334,"Loyal",IF(VALUE(I6)>=234,"Potential",IF(VALUE(I6)>=134,"At Risk",IF(VALUE(I6)>=112,"Churned","Lost"))))) -> Potential
A7: ='Raw Data'!A7 -> 6 | B7: ='Raw Data'!B7 -> Anjali Reddy | C7: ='Raw Data'!E7 -> 4 | D7: ='Raw Data'!F7 -> 15600 | E7: ='Raw Data'!H7 -> 0 | F7: =IF(E7<=30,4,IF(E7<=90,3,IF(E7<=180,2,1))) -> 4 | G7: =IF(C7=1,1,IF(C7=2,2,IF(C7=3,3,4))) -> 4 | H7: =IF(D7<5000,1,IF(D7<15000,2,IF(D7<30000,3,4))) -> 3 | I7: =CONCATENATE(F7,G7,H7) -> 443 | J7: =IF(VALUE(I7)>=434,"Champions",IF(VALUE(I7)>=334,"Loyal",IF(VALUE(I7)>=234,"Potential",IF(VALUE(I7)>=134,"At Risk",IF(VALUE(I7)>=112,"Churned","Lost"))))) -> Champions
A8: ='Raw Data'!A8 -> 7 | B8: ='Raw Data'!B8 -> Rahul Chopra | C8: ='Raw Data'!E8 -> 2 | D8: ='Raw Data'!F8 -> 3800 | E8: ='Raw Data'!H8 -> 193 | F8: =IF(E8<=30,4,IF(E8<=90,3,IF(E8<=180,2,1))) -> 1 | G8: =IF(C8=1,1,IF(C8=2,2,IF(C8=3,3,4))) -> 2 | H8: =IF(D8<5000,1,IF(D8<15000,2,IF(D8<30000,3,4))) -> 1 | I8: =CONCATENATE(F8,G8,H8) -> 121 | J8: =IF(VALUE(I8)>=434,"Champions",IF(VALUE(I8)>=334,"Loyal",IF(VALUE(I8)>=234,"Potential",IF(VALUE(I8)>=134,"At Risk",IF(VALUE(I8)>=112,"Churned","Lost"))))) -> Churned
A9: ='Raw Data'!A9 -> 8 | B9: ='Raw Data'!B9 -> Neha Iyer | C9: ='Raw Data'!E9 -> 3 | D9: ='Raw Data'!F9 -> 12500 | E9: ='Raw Data'!H9 -> 25 | F9: =IF(E9<=30,4,IF(E9<=90,3,IF(E9<=180,2,1))) -> 4 | G9: =IF(C9=1,1,IF(C9=2,2,IF(C9=3,3,4))) -> 3 | H9: =IF(D9<5000,1,IF(D9<15000,2,IF(D9<30000,3,4))) -> 2 | I9: =CONCATENATE(F9,G9,H9) -> 432 | J9: =IF(VALUE(I9)>=434,"Champions",IF(VALUE(I9)>=334,"Loyal",IF(VALUE(I9)>=234,"Potential",IF(VALUE(I9)>=134,"At Risk",IF(VALUE(I9)>=112,"Churned","Lost"))))) -> Loyal
A10: ='Raw Data'!A10 -> 9 | B10: ='Raw Data'!B10 -> Arjun Nair | C10: ='Raw Data'!E10 -> 4 | D10: ='Raw Data'!F10 -> 16800 | E10: ='Raw Data'!H10 -> 4 | F10: =IF(E10<=30,4,IF(E10<=90,3,IF(E10<=180,2,1))) -> 4 | G10: =IF(C10=1,1,IF(C10=2,2,IF(C10=3,3,4))) -> 4 | H10: =IF(D10<5000,1,IF(D10<15000,2,IF(D10<30000,3,4))) -> 3 | I10: =CONCATENATE(F10,G10,H10) -> 443 | J10: =IF(VALUE(I10)>=434,"Champions",IF(VALUE(I10)>=334,"Loyal",IF(VALUE(I10)>=234,"Potential",IF(VALUE(I10)>=134,"At Risk",IF(VALUE(I10)>=112,"Churned","Lost"))))) -> Champions
A11: ='Raw Data'!A11 -> 10 | B11: ='Raw Data'!B11 -> Divya Menon | C11: ='Raw Data'!E11 -> 4 | D11: ='Raw Data'!F11 -> 14200 | E11: ='Raw Data'!H11 -> 29 | F11: =IF(E11<=30,4,IF(E11<=90,3,IF(E11<=180,2,1))) -> 4 | G11: =IF(C11=1,1,IF(C11=2,2,IF(C11=3,3,4))) -> 4 | H11: =IF(D11<5000,1,IF(D11<15000,2,IF(D11<30000,3,4))) -> 2 | I11: =CONCATENATE(F11,G11,H11) -> 442 | J11: =IF(VALUE(I11)>=434,"Champions",IF(VALUE(I11)>=334,"Loyal",IF(VALUE(I11)>=234,"Potential",IF(VALUE(I11)>=134,"At Risk",IF(VALUE(I11)>=112,"Churned","Lost"))))) -> Champions
A12: ='Raw Data'!A12 -> 11 | B12: ='Raw Data'!B12 -> Sanjay Verma | C12: ='Raw Data'!E12 -> 3 | D12: ='Raw Data'!F12 -> 11500 | E12: ='Raw Data'!H12 -> 52 | F12: =IF(E12<=30,4,IF(E12<=90,3,IF(E12<=180,2,1))) -> 3 | G12: =IF(C12=1,1,IF(C12=2,2,IF(C12=3,3,4))) -> 3 | H12: =IF(D12<5000,1,IF(D12<15000,2,IF(D12<30000,3,4))) -> 2 | I12: =CONCATENATE(F12,G12,H12) -> 332 | J12: =IF(VALUE(I12)>=434,"Champions",IF(VALUE(I12)>=334,"Loyal",IF(VALUE(I12)>=234,"Potential",IF(VALUE(I12)>=134,"At Risk",IF(VALUE(I12)>=112,"Churned","Lost"))))) -> Potential
A13: ='Raw Data'!A13 -> 12 | B13: ='Raw Data'!B13 -> Kanika Bhat | C13: ='Raw Data'!E13 -> 1 | D13: ='Raw Data'!F13 -> 2100 | E13: ='Raw Data'!H13 -> 614 | F13: =IF(E13<=30,4,IF(E13<=90,3,IF(E13<=180,2,1))) -> 1 | G13: =IF(C13=1,1,IF(C13=2,2,IF(C13=3,3,4))) -> 1 | H13: =IF(D13<5000,1,IF(D13<15000,2,IF(D13<30000,3,4))) -> 1 | I13: =CONCATENATE(F13,G13,H13) -> 111 | J13: =IF(VALUE(I13)>=434,"Champions",IF(VALUE(I13)>=334,"Loyal",IF(VALUE(I13)>=234,"Potential",IF(VALUE(I13)>=134,"At Risk",IF(VALUE(I13)>=112,"Churned","Lost"))))) -> Lost
... A101: ='Raw Data'!A101 -> 100 | B101: ='Raw Data'!B101 -> Customer 100 | C101: ='Raw Data'!E101 -> 1 | D101: ='Raw Data'!F101 -> 10100 | E101: ='Raw Data'!H101 -> 30 | F101: =IF(E101<=30,4,IF(E101<=90,3,IF(E101<=180,2,1))) -> 4 | G101: =IF(C101=1,1,IF(C101=2,2,IF(C101=3,3,4))) -> 1 | H101: =IF(D101<5000,1,IF(D101<15000,2,IF(D101<30000,3,4))) -> 2 | I101: =CONCATENATE(F101,G101,H101) -> 412 | J101: =IF(VALUE(I101)>=434,"Champions",IF(VALUE(I101)>=334,"Loyal",IF(VALUE(I101)>=234,"Potential",IF(VALUE(I101)>=134,"At Risk",IF(VALUE(I101)>=112,"Churned","Lost"))))) -> Loyal

Sheet Dashboard
A1: RFM ANALYSIS DASHBOARD
A3: Total Customers | C3: Total Revenue | E3: Avg Order Value | G3: Repeat %
A4: =COUNTA('RFM Calculations'!A2:A101) -> 100 | C4: =SUM('RFM Calculations'!D2:D101) -> 777000 | E4: =AVERAGE('RFM Calculations'!D2:D101) -> 7770 | G4: =COUNTIF('RFM Calculations'!C2:C101,">1")/COUNTA('RFM Calculations'!C2:C101) -> 0.79
A6: SEGMENT ANALYSIS
A7: Segment | B7: Count | C7: Revenue | D7: Avg Spend | E7: % Total
A8: Champions | B8: =COUNTIF('RFM Calculations'!J:J,"Champions") -> 14 | C8: =SUMIF('RFM Calculations'!J:J,"Champions",'RFM Calculations'!D:D) -> 152700 | D8: =C8/B8 -> 10907.143 | E8: =C8/SUM($C$8:$C$13) -> 0.1965251
A9: Loyal | B9: =COUNTIF('RFM Calculations'!J:J,"Loyal") -> 43 | C9: =SUMIF('RFM Calculations'!J:J,"Loyal",'RFM Calculations'!D:D) -> 337200 | D9: =C9/B9 -> 7841.8605 | E9: =C9/SUM($C$8:$C$13) -> 0.43397683
A10: Potential | B10: =COUNTIF('RFM Calculations'!J:J,"Potential") -> 39 | C10: =SUMIF('RFM Calculations'!J:J,"Potential",'RFM Calculations'!D:D) -> 271800 | D10: =C10/B10 -> 6969.2308 | E10: =C10/SUM($C$8:$C$13) -> 0.34980695
A11: At Risk | B11: =COUNTIF('RFM Calculations'!J:J,"At Risk") -> 1 | C11: =SUMIF('RFM Calculations'!J:J,"At Risk",'RFM Calculations'!D:D) -> 5200 | D11: =C11/B11 -> 5200 | E11: =C11/SUM($C$8:$C$13) -> 0.0066924067
A12: Churned | B12: =COUNTIF('RFM Calculations'!J:J,"Churned") -> 2 | C12: =SUMIF('RFM Calculations'!J:J,"Churned",'RFM Calculations'!D:D) -> 8000 | D12: =C12/B12 -> 4000 | E12: =C12/SUM($C$8:$C$13) -> 0.01029601
A13: Lost | B13: =COUNTIF('RFM Calculations'!J:J,"Lost") -> 1 | C13: =SUMIF('RFM Calculations'!J:J,"Lost",'RFM Calculations'!D:D) -> 2100 | D13: =C13/B13 -> 2100 | E13: =C13/SUM($C$8:$C$13) -> 0.0027027027
A14: TOTAL | B14: =SUM(B8:B13) -> 100 | C14: =SUM(C8:C13) -> 777000 | E14: 100%

Sheet Recommendations
A1: SEGMENT-BASED RECOMMENDATIONS
A2: Champions
A3: Customers: | B3: =COUNTIF('RFM Calculations'!J:J,"Champions") -> 14
A4: Revenue: | B4: =SUMIF('RFM Calculations'!J:J,"Champions",'RFM Calculations'!D:D) -> 152700
A5: Goal: | B5: Maximize lifetime value and loyalty
A6: Actions:
B7: • VIP loyalty program with exclusive benefits
B8: • Personal account manager
B9: • Exclusive product access
B10: • Premium customer service
B11: • Quarterly business reviews
A12: Frequency: | B12: Monthly touchpoints
A13: Expected ROI: | B13: 20-30% increase
A15: Loyal
A16: Customers: | B16: =COUNTIF('RFM Calculations'!J:J,"Loyal") -> 43
A17: Revenue: | B17: =SUMIF('RFM Calculations'!J:J,"Loyal",'RFM Calculations'!D:D) -> 337200
A18: Goal: | B18: Move to Champions tier
A19: Actions:
B20: • Loyalty rewards program
B21: • Cross-sell recommendations
B22: • Birthday and anniversary gifts
B23: • Member-only events
B24: • Product education
A25: Frequency: | B25: Bi-monthly
A26: Expected ROI: | B26: 15-20% conversion
A28: Potential
A29: Customers: | B29: =COUNTIF('RFM Calculations'!J:J,"Potential") -> 39
A30: Revenue: | B30: =SUMIF('RFM Calculations'!J:J,"Potential",'RFM Calculations'!D:D) -> 271800
A31: Goal: | B31: Increase engagement and spending
A32: Actions:
B33: • Personalized email campaigns
B34: • Limited-time special offers
B35: • Product education webinars
B36: • Free trial programs
B37: • Referral incentives
A38: Frequency: | B38: Monthly
A39: Expected ROI: | B39: 10-15% conversion
A41: At Risk
A42: Customers: | B42: =COUNTIF('RFM Calculations'!J:J,"At Risk") -> 1
A43: Revenue: | B43: =SUMIF('RFM Calculations'!J:J,"At Risk",'RFM Calculations'!D:D) -> 5200
...

Sheet Formulas Reference
A1: ALL FORMULAS REFERENCE
A3: Location | B3: Cell | C3: Formula Name | D3: Formula
A4: Sheet 2 | B4: F2:F101 | C4: R_Quartile | D4: =IF(E2<=30,4,IF(E2<=90,3,IF(E2<=180,2,1))) -> 4
A5: Sheet 2 | B5: G2:G101 | C5: F_Quartile | D5: =IF(C2=1,1,IF(C2=2,2,IF(C2=3,3,4))) -> 4
A6: Sheet 2 | B6: H2:H101 | C6: M_Quartile | D6: =IF(D2<5000,1,IF(D2<15000,2,IF(D2<30000,3,4))) -> 1
A7: Sheet 2 | B7: I2:I101 | C7: RFM Score | D7: =CONCATENATE(F2,G2,H2)
A8: Sheet 2 | B8: J2:J101 | C8: Segment
A9: Sheet 3 | B9: A4 | C9: Total Customers
A10: Sheet 3 | B10: C4 | C10: Total Revenue
A11: Sheet 3 | B11: E4 | C11: Avg Order Value
A12: Sheet 3 | B12: G4 | C12: Repeat %
A13: Sheet 3 | B13: B8:B13 | C13: Count by Segment
A14: Sheet 3 | B14: C8:C13 | C14: Revenue by Segment
A15: Sheet 3 | B15: D8:D13 | C15: Avg Spend
A16: Sheet 3 | B16: E8:E13 | C16: % of Total
